Workbook
Name Slicer_Order_Date: #N/A
Name Slicer_Product_Category: #N/A
Name Slicer_Region: #N/A

Sheet Sales_Performance_Analysis.csv
A1: Order ID | B1: Order Date | C1: Region | D1: Product Category | E1: Sales Amount | F1: Quantity Sold | G1: Discount (%) | H1: Profit
A2: ab899d2f | B2: 45022 | C2: norTh | D2: groceries | E2: 859.29 | F2: 44 | G2: 37 | H2: 1653.87
A3: 73484eb1 | B3: 45412 | C3: Mes$t | D3: groceries | E3: 1546.81 | F3: 23 | G3: 33 | H3: 1932.71
A4: 19395924 | B4: 45363 | C4: eAsT | D4: groceries | E4: 4703.58 | F4: 31 | G4: 15 | H4: 527.47
A5: b3fded3d | B5: 45331 | C5: eAsT | D5: groceries | E5: 3377.17 | F5: 47 | G5: 3 | H5: 482.65
A6: 6e4bdd51 | B6: 45502 | C6: $0uTH | D6: Cloth ing | E6: 3517.49 | F6: 6 | G6: 28 | H6: 748.72
A7: 21d88d69 | B7: 45164 | C7: eAsT | D7: FURNiture | E7: 362.55 | F7: 19 | G7: 50 | H7: 314.71
A8: 9da2704d | B8: 45572 | C8: eAsT | D8: sports | E8: 4811.17 | F8: 22 | G8: 18 | H8: 1372.89
A9: a1bd6815 | B9: 45000 | C9: Mes$t | D9: electronicS | E9: 3565.2 | F9: 22 | G9: 16 | H9: 1437.3
A10: 0bbd51fc | B10: 45106 | C10: eAsT | D10: Cloth ing | E10: 3805.25 | F10: 19 | G10: 3 | H10: 1537.28
A11: 8bf7e4b3 | B11: 44998 | C11: $0uTH | D11: Cloth ing | E11: 2178.72 | F11: 15 | G11: 24 | H11: 1696.65
A12: e6cf1255 | B12: 45439 | C12: Mes$t | D12: groceries | E12: 2844.93 | F12: 34 | G12: 12 | H12: 1166.39
A13: 3ba1fc5c | B13: 45291 | C13: Mes$t | D13: electronicS | E13: 3600.04 | F13: 10 | G13: 2 | H13: 1632.75
A14: 388ff70d | B14: 45239 | C14: eAsT | D14: $port$ | E14: 941.88 | F14: 13 | G14: 28 | H14: 646.49
A15: ce2e9002 | B15: 44919 | C15: $0uTH | D15: $port$ | E15: 3300.86 | F15: 1 | G15: 48 | H15: 86.9
A16: a4f9a338 | B16: 45329 | C16: eAsT | D16: groceries | E16: 1081.62 | F16: 4 | G16: 19 | H16: 611.06
... A19: 35358e9c | B19: 45471 | C19: norTh | D19: Cloth ing | E19: 2784.79 | F19: 35 | G19: 40 | H19: 999.6
A20: 31676338 | B20: 45246 | C20: $0uTH | D20: Cloth ing | E20: 1082.98 | F20: 8 | G20: 11 | H20: 1604.19
A21: 05d72e20 | B21: 45556 | C21: eAsT | D21: Cloth ing | E21: 787.79 | F21: 47 | G21: 18 | H21: 1313.33
A22: 68dbe328 | B22: 45566 | C22: $0uTH | D22: FURNiture | E22: 312.7 | F22: 36 | G22: 43 | H22: 559.52
A23: 78d3f47b | B23: 45077 | C23: eAsT | D23: $port$ | E23: 265.32 | F23: 21 | G23: 36 | H23: 595.91
A24: 9e4d1fe0 | B24: 45400 | C24: Mes$t | D24: FURNiture | E24: 1253.64 | F24: 35 | G24: 14 | H24: 1653.66
A25: 9215a70e | B25: 45341 | C25: Mes$t | D25: Cloth ing | E25: 1874.07 | F25: 28 | G25: 23 | H25: 1783.26
A26: 54ca3433 | B26: 45041 | C26: eAsT | D26: Cloth ing | E26: 2561.71 | F26: 44 | G26: 10 | H26: 800.82
A27: 0ba75cc7 | B27: 45059 | C27: Mes$t | D27: $port$ | E27: 1960.74 | F27: 50 | G27: 6 | H27: 1530.61
A28: 601860b1 | B28: 45037 | C28: eAsT | D28: electronicS | E28: 2415.44 | F28: 35 | G28: 14 | H28: 335.57
A29: e393e106 | B29: 45290 | C29: eAsT | D29: electronicS | E29: 2284.22 | F29: 8 | G29: 41 | H29: 1866.59
A30: 7ab3d472 | B30: 44885 | C30: Mes$t | D30: $port$ | E30: 2118.55 | F30: 29 | G30: 24 | H30: 702.15
A31: 01d9b1ae | B31: 45248 | C31: $0uTH | D31: groceries | E31: 4803.6 | F31: 11 | G31: 12 | H31: 1086.74
A32: 20385cb6 | B32: 45533 | C32: norTh | D32: groceries | E32: 4297 | F32: 17 | G32: 49 | H32: 678.7
... A69: 92458ed3 | B69: 45024 | C69: norTh | D69: FURNiture | E69: 1356.62 | F69: 2 | G69: 21 | H69: 1213.34
A70: 76740552 | B70: 45201 | C70: $0uTH | D70: electronicS | E70: 2905.8 | F70: 20 | G70: 10 | H70: 1417.43
A71: f92de80d | B71: 45060 | C71: $0uTH | D71: FURNiture | E71: 2065.42 | F71: 22 | G71: 15 | H71: 787.51
A72: 647ff51a | B72: 45094 | C72: eAsT | D72: Cloth ing | E72: 272.88 | F72: 47 | G72: 29 | H72: 1208.68
A73: f8548ec7 | B73: 45594 | C73: eAsT | D73: Cloth ing | E73: 4126.4 | F73: 34 | G73: 13 | H73: 1690.11
A74: 7855a0d2 | B74: 45195 | C74: norTh | D74: FURNiture | E74: 4204.55 | F74: 49 | G74: 1 | H74: 1534.82
A75: bf586512 | B75: 45226 | C75: Mes$t | D75: Cloth ing | E75: 2130.98 | F75: 7 | G75: 29 | H75: 679.16
A76: deea1965 | B76: 45436 | C76: $0uTH | D76: FURNiture | E76: 1253.28 | F76: 4 | G76: 48 | H76: 317.33
A77: a0a8290f | B77: 45478 | C77: $0uTH | D77: $port$ | E77: 1050.29 | F77: 30 | G77: 4 | H77: 423.5
A78: 077a9429 | B78: 45079 | C78: norTh | D78: FURNiture | E78: 1269.1 | F78: 3 | G78: 7 | H78: 1819.88
...

Sheet Data cleaning
A1: Order ID | B1: Order Date | C1: Region | D1: Product Category | E1: Sales Amount | F1: Quantity Sold | G1: Discount (%) | H1: Profit | L1: order id | M1: Order Date | N1: Region | O1: Product Category | P1: Sales Amount | Q1: Quantity Sold | R1: Discount % | S1: profit
A2: ab899d2f | B2: 45022 | C2: North | D2: Groceries | E2: 859.29 | F2: 44 | G2: 37 | H2: 1653.87 | L2: =TRIM(A2) -> ab899d2f | M2: 45022 | N2: =PROPER(Table1[[#This Row],[Region]]) -> North | O2: =PROPER(Table1[[#This Row],[Product Category]]) -> Groceries | P2: =ROUND(Table1[[#This Row],[Sales Amount]],1) -> 859.3 | Q2: =Table1[[#This Row],[Quantity Sold]] -> 44 | R2: =Table1[[#This Row],[Discount (%)]] -> 37 | S2: =Table1[[#This Row],[Profit]] -> 1653.87
A3: 73484eb1 | B3: 45023 | C3: West | D3: Groceries | E3: 1546.81 | F3: 23 | G3: 33 | H3: 1932.71 | L3: =TRIM(A3) -> 73484eb1 | M3: 45023 | N3: =PROPER(Table1[[#This Row],[Region]]) -> West | O3: =PROPER(Table1[[#This Row],[Product Category]]) -> Groceries | P3: =ROUND(Table1[[#This Row],[Sales Amount]],1) -> 1546.8 | Q3: =Table1[[#This Row],[Quantity Sold]] -> 23 | R3: =Table1[[#This Row],[Discount (%)]] -> 33 | S3: =Table1[[#This Row],[Profit]] -> 1932.71
A4: 19395924 | B4: 45024 | C4: East | D4: Groceries | E4: 4703.58 | F4: 31 | G4: 15 | H4: 527.47 | L4: =TRIM(A4) -> 19395924 | M4: 45024 | N4: =PROPER(Table1[[#This Row],[Region]]) -> East | O4: =PROPER(Table1[[#This Row],[Product Category]]) -> Groceries | P4: =ROUND(Table1[[#This Row],[Sales Amount]],1) -> 4703.6 | Q4: =Table1[[#This Row],[Quantity Sold]] -> 31 | R4: =Table1[[#This Row],[Discount (%)]] -> 15 | S4: =Table1[[#This Row],[Profit]] -> 527.47
A5: b3fded3d | B5: 45025 | C5: East | D5: Groceries | E5: 3377.17 | F5: 47 | G5: 3 | H5: 482.65 | L5: =TRIM(A5) -> b3fded3d | M5: 45025 | N5: =PROPER(Table1[[#This Row],[Region]]) -> East | O5: =PROPER(Table1[[#This Row],[Product Category]]) -> Groceries | P5: =ROUND(Table1[[#This Row],[Sales Amount]],1) -> 3377.2 | Q5: =Table1[[#This Row],[Quantity Sold]] -> 47 | R5: =Table1[[#This Row],[Discount (%)]] -> 3 | S5: =Table1[[#This Row],[Profit]] -> 482.65
A6: 6e4bdd51 | B6: 45026 | C6: South | D6: Clothing | E6: 3517.49 | F6: 6 | G6: 28 | H6: 748.72 | L6: =TRIM(A6) -> 6e4bdd51 | M6: 45026 | N6: =PROPER(Table1[[#This Row],[Region]]) -> South | O6: =PROPER(Table1[[#This Row],[Product Category]]) -> Clothing | P6: =ROUND(Table1[[#This Row],[Sales Amount]],1) -> 3517.5 | Q6: =Table1[[#This Row],[Quantity Sold]] -> 6 | R6: =Table1[[#This Row],[Discount (%)]] -> 28 | S6: =Table1[[#This Row],[Profit]] -> 748.72
A7: 21d88d69 | B7: 45027 | C7: East | D7: Furniture | E7: 362.55 | F7: 19 | G7: 50 | H7: 314.71 | L7: =TRIM(A7) -> 21d88d69 | M7: 45027 | N7: =PROPER(Table1[[#This Row],[Region]]) -> East | O7: =PROPER(Table1[[#This Row],[Product Category]]) -> Furniture | P7: =ROUND(Table1[[#This Row],[Sales Amount]],1) -> 362.6 | Q7: =Table1[[#This Row],[Quantity Sold]] -> 19 | R7: =Table1[[#This Row],[Discount (%)]] -> 50 | S7: =Table1[[#This Row],[Profit]] -> 314.71
A8: 9da2704d | B8: 45028 | C8: East | D8: Sports | E8: 4811.17 | F8: 22 | G8: 18 | H8: 1372.89 | L8: =TRIM(A8) -> 9da2704d | M8: 45028 | N8: =PROPER(Table1[[#This Row],[Region]]) -> East | O8: =PROPER(Table1[[#This Row],[Product Category]]) -> Sports | P8: =ROUND(Table1[[#This Row],[Sales Amount]],1) -> 4811.2 | Q8: =Table1[[#This Row],[Quantity Sold]] -> 22 | R8: =Table1[[#This Row],[Discount (%)]] -> 18 | S8: =Table1[[#This Row],[Profit]] -> 1372.89
A9: a1bd6815 | B9: 45029 | C9: West | D9: Electronics | E9: 3565.2 | F9: 22 | G9: 16 | H9: 1437.3 | L9: =TRIM(A9) -> a1bd6815 | M9: 45029 | N9: =PROPER(Table1[[#This Row],[Region]]) -> West | O9: =PROPER(Table1[[#This Row],[Product Category]]) -> Electronics | P9: =ROUND(Table1[[#This Row],[Sales Amount]],1) -> 3565.2 | Q9: =Table1[[#This Row],[Quantity Sold]] -> 22 | R9: =Table1[[#This Row],[Discount (%)]] -> 16 | S9: =Table1[[#This Row],[Profit]] -> 1437.3
A10: 0bbd51fc | B10: 45030 | C10: East | D10: Clothing | E10: 3805.25 | F10: 19 | G10: 3 | H10: 1537.28 | L10: =TRIM(A10) -> 0bbd51fc | M10: 45030 | N10: =PROPER(Table1[[#This Row],[Region]]) -> East | O10: =PROPER(Table1[[#This Row],[Product Category]]) -> Clothing | P10: =ROUND(Table1[[#This Row],[Sales Amount]],1) -> 3805.3 | Q10: =Table1[[#This Row],[Quantity Sold]] -> 19 | R10: =Table1[[#This Row],[Discount (%)]] -> 3 | S10: =Table1[[#This Row],[Profit]] -> 1537.28
A11: 8bf7e4b3 | B11: 45031 | C11: South | D11: Clothing | E11: 2178.72 | F11: 15 | G11: 24 | H11: 1696.65 | L11: =TRIM(A11) -> 8bf7e4b3 | M11: 45031 | N11: =PROPER(Table1[[#This Row],[Region]]) -> South | O11: =PROPER(Table1[[#This Row],[Product Category]]) -> Clothing | P11: =ROUND(Table1[[#This Row],[Sales Amount]],1) -> 2178.7 | Q11: =Table1[[#This Row],[Quantity Sold]] -> 15 | R11: =Table1[[#This Row],[Discount (%)]] -> 24 | S11: =Table1[[#This Row],[Profit]] -> 1696.65
A12: e6cf1255 | B12: 45032 | C12: West | D12: Groceries | E12: 2844.93 | F12: 34 | G12: 12 | H12: 1166.39 | L12: =TRIM(A12) -> e6cf1255 | M12: 45032 | N12: =PROPER(Table1[[#This Row],[Region]]) -> West | O12: =PROPER(Table1[[#This Row],[Product Category]]) -> Groceries | P12: =ROUND(Table1[[#This Row],[Sales Amount]],1) -> 2844.9 | Q12: =Table1[[#This Row],[Quantity Sold]] -> 34 | R12: =Table1[[#This Row],[Discount (%)]] -> 12 | S12: =Table1[[#This Row],[Profit]] -> 1166.39
A13: 3ba1fc5c | B13: 45033 | C13: West | D13: Electronics | E13: 3600.04 | F13: 10 | G13: 2 | H13: 1632.75 | L13: =TRIM(A13) -> 3ba1fc5c | M13: 45033 | N13: =PROPER(Table1[[#This Row],[Region]]) -> West | O13: =PROPER(Table1[[#This Row],[Product Category]]) -> Electronics | P13: =ROUND(Table1[[#This Row],[Sales Amount]],1) -> 3600 | Q13: =Table1[[#This Row],[Quantity Sold]] -> 10 | R13: =Table1[[#This Row],[Discount (%)]] -> 2 | S13: =Table1[[#This Row],[Profit]] -> 1632.75
A14: 388ff70d | B14: 45034 | C14: East | D14: Sports | E14: 941.88 | F14: 13 | G14: 28 | H14: 646.49 | L14: =TRIM(A14) -> 388ff70d | M14: 45034 | N14: =PROPER(Table1[[#This Row],[Region]]) -> East | O14: =PROPER(Table1[[#This Row],[Product Category]]) -> Sports | P14: =ROUND(Table1[[#This Row],[Sales Amount]],1) -> 941.9 | Q14: =Table1[[#This Row],[Quantity Sold]] -> 13 | R14: =Table1[[#This Row],[Discount (%)]] -> 28 | S14: =Table1[[#This Row],[Profit]] -> 646.49
A15: ce2e9002 | B15: 45035 | C15: South | D15: Sports | E15: 3300.86 | F15: 1 | G15: 48 | H15: 86.9 | L15: =TRIM(A15) -> ce2e9002 | M15: 45035 | N15: =PROPER(Table1[[#This Row],[Region]]) -> South | O15: =PROPER(Table1[[#This Row],[Product Category]]) -> Sports | P15: =ROUND(Table1[[#This Row],[Sales Amount]],1) -> 3300.9 | Q15: =Table1[[#This Row],[Quantity Sold]] -> 1 | R15: =Table1[[#This Row],[Discount (%)]] -> 48 | S15: =Table1[[#This Row],[Profit]] -> 86.9
A16: a4f9a338 | B16: 45036 | C16: East | D16: Groceries | E16: 1081.62 | F16: 4 | G16: 19 | H16: 611.06 | L16: =TRIM(A16) -> a4f9a338 | M16: 45036 | N16: =PROPER(Table1[[#This Row],[Region]]) -> East | O16: =PROPER(Table1[[#This Row],[Product Category]]) -> Groceries | P16: =ROUND(Table1[[#This Row],[Sales Amount]],1) -> 1081.6 | Q16: =Table1[[#This Row],[Quantity Sold]] -> 4 | R16: =Table1[[#This Row],[Discount (%)]] -> 19 | S16: =Table1[[#This Row],[Profit]] -> 611.06
... A19: 35358e9c | B19: 45039 | C19: North | D19: Clothing | E19: 2784.79 | F19: 35 | G19: 40 | H19: 999.6 | L19: =TRIM(A19) -> 35358e9c | M19: 45039 | N19: =PROPER(Table1[[#This Row],[Region]]) -> North | O19: =PROPER(Table1[[#This Row],[Product Category]]) -> Clothing | P19: =ROUND(Table1[[#This Row],[Sales Amount]],1) -> 2784.8 | Q19: =Table1[[#This Row],[Quantity Sold]] -> 35 | R19: =Table1[[#This Row],[Discount (%)]] -> 40 | S19: =Table1[[#This Row],[Profit]] -> 999.6
A20: 31676338 | B20: 45040 | C20: South | D20: Clothing | E20: 1082.98 | F20: 8 | G20: 11 | H20: 1604.19 | L20: =TRIM(A20) -> 31676338 | M20: 45040 | N20: =PROPER(Table1[[#This Row],[Region]]) -> South | O20: =PROPER(Table1[[#This Row],[Product Category]]) -> Clothing | P20: =ROUND(Table1[[#This Row],[Sales Amount]],1) -> 1083 | Q20: =Table1[[#This Row],[Quantity Sold]] -> 8 | R20: =Table1[[#This Row],[Discount (%)]] -> 11 | S20: =Table1[[#This Row],[Profit]] -> 1604.19
A21: 05d72e20 | B21: 45041 | C21: East | D21: Clothing | E21: 787.79 | F21: 47 | G21: 18 | H21: 1313.33 | L21: =TRIM(A21) -> 05d72e20 | M21: 45041 | N21: =PROPER(Table1[[#This Row],[Region]]) -> East | O21: =PROPER(Table1[[#This Row],[Product Category]]) -> Clothing | P21: =ROUND(Table1[[#This Row],[Sales Amount]],1) -> 787.8 | Q21: =Table1[[#This Row],[Quantity Sold]] -> 47 | R21: =Table1[[#This Row],[Discount (%)]] -> 18 | S21: =Table1[[#This Row],[Profit]] -> 1313.33
A22: 68dbe328 | B22: 45042 | C22: South | D22: Furniture | E22: 312.7 | F22: 36 | G22: 43 | H22: 559.52 | L22: =TRIM(A22) -> 68dbe328 | M22: 45042 | N22: =PROPER(Table1[[#This Row],[Region]]) -> South | O22: =PROPER(Table1[[#This Row],[Product Category]]) -> Furniture | P22: =ROUND(Table1[[#This Row],[Sales Amount]],1) -> 312.7 | Q22: =Table1[[#This Row],[Quantity Sold]] -> 36 | R22: =Table1[[#This Row],[Discount (%)]] -> 43 | S22: =Table1[[#This Row],[Profit]] -> 559.52
A23: 78d3f47b | B23: 45043 | C23: East | D23: Sports | E23: 265.32 | F23: 21 | G23: 36 | H23: 595.91 | L23: =TRIM(A23) -> 78d3f47b | M23: 45043 | N23: =PROPER(Table1[[#This Row],[Region]]) -> East | O23: =PROPER(Table1[[#This Row],[Product Category]]) -> Sports | P23: =ROUND(Table1[[#This Row],[Sales Amount]],1) -> 265.3 | Q23: =Table1[[#This Row],[Quantity Sold]] -> 21 | R23: =Table1[[#This Row],[Discount (%)]] -> 36 | S23: =Table1[[#This Row],[Profit]] -> 595.91
A24: 9e4d1fe0 | B24: 45044 | C24: West | D24: Furniture | E24: 1253.64 | F24: 35 | G24: 14 | H24: 1653.66 | L24: =TRIM(A24) -> 9e4d1fe0 | M24: 45044 | N24: =PROPER(Table1[[#This Row],[Region]]) -> West | O24: =PROPER(Table1[[#This Row],[Product Category]]) -> Furniture | P24: =ROUND(Table1[[#This Row],[Sales Amount]],1) -> 1253.6 | Q24: =Table1[[#This Row],[Quantity Sold]] -> 35 | R24: =Table1[[#This Row],[Discount (%)]] -> 14 | S24: =Table1[[#This Row],[Profit]] -> 1653.66
A25: 9215a70e | B25: 45045 | C25: West | D25: Clothing | E25: 1874.07 | F25: 28 | G25: 23 | H25: 1783.26 | L25: =TRIM(A25) -> 9215a70e | M25: 45045 | N25: =PROPER(Table1[[#This Row],[Region]]) -> West | O25: =PROPER(Table1[[#This Row],[Product Category]]) -> Clothing | P25: =ROUND(Table1[[#This Row],[Sales Amount]],1) -> 1874.1 | Q25: =Table1[[#This Row],[Quantity Sold]] -> 28 | R25: =Table1[[#This Row],[Discount (%)]] -> 23 | S25: =Table1[[#This Row],[Profit]] -> 1783.26
A26: 54ca3433 | B26: 45046 | C26: East | D26: Clothing | E26: 2561.71 | F26: 44 | G26: 10 | H26: 800.82 | L26: =TRIM(A26) -> 54ca3433 | M26: 45046 | N26: =PROPER(Table1[[#This Row],[Region]]) -> East | O26: =PROPER(Table1[[#This Row],[Product Category]]) -> Clothing | P26: =ROUND(Table1[[#This Row],[Sales Amount]],1) -> 2561.7 | Q26: =Table1[[#This Row],[Quantity Sold]] -> 44 | R26: =Table1[[#This Row],[Discount (%)]] -> 10 | S26: =Table1[[#This Row],[Profit]] -> 800.82
A27: 0ba75cc7 | B27: 45047 | C27: West | D27: Sports | E27: 1960.74 | F27: 50 | G27: 6 | H27: 1530.61 | L27: =TRIM(A27) -> 0ba75cc7 | M27: 45047 | N27: =PROPER(Table1[[#This Row],[Region]]) -> West | O27: =PROPER(Table1[[#This Row],[Product Category]]) -> Sports | P27: =ROUND(Table1[[#This Row],[Sales Amount]],1) -> 1960.7 | Q27: =Table1[[#This Row],[Quantity Sold]] -> 50 | R27: =Table1[[#This Row],[Discount (%)]] -> 6 | S27: =Table1[[#This Row],[Profit]] -> 1530.61
A28: 601860b1 | B28: 45048 | C28: East | D28: Electronics | E28: 2415.44 | F28: 35 | G28: 14 | H28: 335.57 | L28: =TRIM(A28) -> 601860b1 | M28: 45048 | N28: =PROPER(Table1[[#This Row],[Region]]) -> East | O28: =PROPER(Table1[[#This Row],[Product Category]]) -> Electronics | P28: =ROUND(Table1[[#This Row],[Sales Amount]],1) -> 2415.4 | Q28: =Table1[[#This Row],[Quantity Sold]] -> 35 | R28: =Table1[[#This Row],[Discount (%)]] -> 14 | S28: =Table1[[#This Row],[Profit]] -> 335.57
A29: e393e106 | B29: 45049 | C29: East | D29: Electronics | E29: 2284.22 | F29: 8 | G29: 41 | H29: 1866.59 | L29: =TRIM(A29) -> e393e106 | M29: 45049 | N29: =PROPER(Table1[[#This Row],[Region]]) -> East | O29: =PROPER(Table1[[#This Row],[Product Category]]) -> Electronics | P29: =ROUND(Table1[[#This Row],[Sales Amount]],1) -> 2284.2 | Q29: =Table1[[#This Row],[Quantity Sold]] -> 8 | R29: =Table1[[#This Row],[Discount (%)]] -> 41 | S29: =Table1[[#This Row],[Profit]] -> 1866.59
A30: 7ab3d472 | B30: 45050 | C30: West | D30: Sports | E30: 2118.55 | F30: 29 | G30: 24 | H30: 702.15 | L30: =TRIM(A30) -> 7ab3d472 | M30: 45050 | N30: =PROPER(Table1[[#This Row],[Region]]) -> West | O30: =PROPER(Table1[[#This Row],[Product Category]]) -> Sports | P30: =ROUND(Table1[[#This Row],[Sales Amount]],1) -> 2118.6 | Q30: =Table1[[#This Row],[Quantity Sold]] -> 29 | R30: =Table1[[#This Row],[Discount (%)]] -> 24 | S30: =Table1[[#This Row],[Profit]] -> 702.15
A31: 01d9b1ae | B31: 45051 | C31: South | D31: Groceries | E31: 4803.6 | F31: 11 | G31: 12 | H31: 1086.74 | L31: =TRIM(A31) -> 01d9b1ae | M31: 45051 | N31: =PROPER(Table1[[#This Row],[Region]]) -> South | O31: =PROPER(Table1[[#This Row],[Product Category]]) -> Groceries | P31: =ROUND(Table1[[#This Row],[Sales Amount]],1) -> 4803.6 | Q31: =Table1[[#This Row],[Quantity Sold]] -> 11 | R31: =Table1[[#This Row],[Discount (%)]] -> 12 | S31: =Table1[[#This Row],[Profit]] -> 1086.74
A32: 20385cb6 | B32: 45052 | C32: North | D32: Groceries | E32: 4297 | F32: 17 | G32: 49 | H32: 678.7 | L32: =TRIM(A32) -> 20385cb6 | M32: 45052 | N32: =PROPER(Table1[[#This Row],[Region]]) -> North | O32: =PROPER(Table1[[#This Row],[Product Category]]) -> Groceries | P32: =ROUND(Table1[[#This Row],[Sales Amount]],1) -> 4297 | Q32: =Table1[[#This Row],[Quantity Sold]] -> 17 | R32: =Table1[[#This Row],[Discount (%)]] -> 49 | S32: =Table1[[#This Row],[Profit]] -> 678.7
... A69: 92458ed3 | B69: 45089 | C69: North | D69: Furniture | E69: 1356.62 | F69: 2 | G69: 21 | H69: 1213.34 | L69: =TRIM(A69) -> 92458ed3 | M69: 45089 | N69: =PROPER(Table1[[#This Row],[Region]]) -> North | O69: =PROPER(Table1[[#This Row],[Product Category]]) -> Furniture | P69: =ROUND(Table1[[#This Row],[Sales Amount]],1) -> 1356.6 | Q69: =Table1[[#This Row],[Quantity Sold]] -> 2 | R69: =Table1[[#This Row],[Discount (%)]] -> 21 | S69: =Table1[[#This Row],[Profit]] -> 1213.34
A70: 76740552 | B70: 45090 | C70: South | D70: Electronics | E70: 2905.8 | F70: 20 | G70: 10 | H70: 1417.43 | L70: =TRIM(A70) -> 76740552 | M70: 45090 | N70: =PROPER(Table1[[#This Row],[Region]]) -> South | O70: =PROPER(Table1[[#This Row],[Product Category]]) -> Electronics | P70: =ROUND(Table1[[#This Row],[Sales Amount]],1) -> 2905.8 | Q70: =Table1[[#This Row],[Quantity Sold]] -> 20 | R70: =Table1[[#This Row],[Discount (%)]] -> 10 | S70: =Table1[[#This Row],[Profit]] -> 1417.43
A71: f92de80d | B71: 45091 | C71: South | D71: Furniture | E71: 2065.42 | F71: 22 | G71: 15 | H71: 787.51 | L71: =TRIM(A71) -> f92de80d | M71: 45091 | N71: =PROPER(Table1[[#This Row],[Region]]) -> South | O71: =PROPER(Table1[[#This Row],[Product Category]]) -> Furniture | P71: =ROUND(Table1[[#This Row],[Sales Amount]],1) -> 2065.4 | Q71: =Table1[[#This Row],[Quantity Sold]] -> 22 | R71: =Table1[[#This Row],[Discount (%)]] -> 15 | S71: =Table1[[#This Row],[Profit]] -> 787.51
A72: 647ff51a | B72: 45092 | C72: East | D72: Clothing | E72: 272.88 | F72: 47 | G72: 29 | H72: 1208.68 | L72: =TRIM(A72) -> 647ff51a | M72: 45092 | N72: =PROPER(Table1[[#This Row],[Region]]) -> East | O72: =PROPER(Table1[[#This Row],[Product Category]]) -> Clothing | P72: =ROUND(Table1[[#This Row],[Sales Amount]],1) -> 272.9 | Q72: =Table1[[#This Row],[Quantity Sold]] -> 47 | R72: =Table1[[#This Row],[Discount (%)]] -> 29 | S72: =Table1[[#This Row],[Profit]] -> 1208.68
A73: f8548ec7 | B73: 45093 | C73: East | D73: Clothing | E73: 4126.4 | F73: 34 | G73: 13 | H73: 1690.11 | L73: =TRIM(A73) -> f8548ec7 | M73: 45093 | N73: =PROPER(Table1[[#This Row],[Region]]) -> East | O73: =PROPER(Table1[[#This Row],[Product Category]]) -> Clothing | P73: =ROUND(Table1[[#This Row],[Sales Amount]],1) -> 4126.4 | Q73: =Table1[[#This Row],[Quantity Sold]] -> 34 | R73: =Table1[[#This Row],[Discount (%)]] -> 13 | S73: =Table1[[#This Row],[Profit]] -> 1690.11
A74: 7855a0d2 | B74: 45094 | C74: North | D74: Furniture | E74: 4204.55 | F74: 49 | G74: 1 | H74: 1534.82 | L74: =TRIM(A74) -> 7855a0d2 | M74: 45094 | N74: =PROPER(Table1[[#This Row],[Region]]) -> North | O74: =PROPER(Table1[[#This Row],[Product Category]]) -> Furniture | P74: =ROUND(Table1[[#This Row],[Sales Amount]],1) -> 4204.6 | Q74: =Table1[[#This Row],[Quantity Sold]] -> 49 | R74: =Table1[[#This Row],[Discount (%)]] -> 1 | S74: =Table1[[#This Row],[Profit]] -> 1534.82
A75: bf586512 | B75: 45095 | C75: West | D75: Clothing | E75: 2130.98 | F75: 7 | G75: 29 | H75: 679.16 | L75: =TRIM(A75) -> bf586512 | M75: 45095 | N75: =PROPER(Table1[[#This Row],[Region]]) -> West | O75: =PROPER(Table1[[#This Row],[Product Category]]) -> Clothing | P75: =ROUND(Table1[[#This Row],[Sales Amount]],1) -> 2131 | Q75: =Table1[[#This Row],[Quantity Sold]] -> 7 | R75: =Table1[[#This Row],[Discount (%)]] -> 29 | S75: =Table1[[#This Row],[Profit]] -> 679.16
A76: deea1965 | B76: 45096 | C76: South | D76: Furniture | E76: 1253.28 | F76: 4 | G76: 48 | H76: 317.33 | L76: =TRIM(A76) -> deea1965 | M76: 45096 | N76: =PROPER(Table1[[#This Row],[Region]]) -> South | O76: =PROPER(Table1[[#This Row],[Product Category]]) -> Furniture | P76: =ROUND(Table1[[#This Row],[Sales Amount]],1) -> 1253.3 | Q76: =Table1[[#This Row],[Quantity Sold]] -> 4 | R76: =Table1[[#This Row],[Discount (%)]] -> 48 | S76: =Table1[[#This Row],[Profit]] -> 317.33
A77: a0a8290f | B77: 45097 | C77: South | D77: Sports | E77: 1050.29 | F77: 30 | G77: 4 | H77: 423.5 | L77: =TRIM(A77) -> a0a8290f | M77: 45097 | N77: =PROPER(Table1[[#This Row],[Region]]) -> South | O77: =PROPER(Table1[[#This Row],[Product Category]]) -> Sports | P77: =ROUND(Table1[[#This Row],[Sales Amount]],1) -> 1050.3 | Q77: =Table1[[#This Row],[Quantity Sold]] -> 30 | R77: =Table1[[#This Row],[Discount (%)]] -> 4 | S77: =Table1[[#This Row],[Profit]] -> 423.5
A78: 077a9429 | B78: 45098 | C78: North | D78: Furniture | E78: 1269.1 | F78: 3 | G78: 7 | H78: 1819.88 | L78: =TRIM(A78) -> 077a9429 | M78: 45098 | N78: =PROPER(Table1[[#This Row],[Region]]) -> North | O78: =PROPER(Table1[[#This Row],[Product Category]]) -> Furniture | P78: =ROUND(Table1[[#This Row],[Sales Amount]],1) -> 1269.1 | Q78: =Table1[[#This Row],[Quantity Sold]] -> 3 | R78: =Table1[[#This Row],[Discount (%)]] -> 7 | S78: =Table1[[#This Row],[Profit]] -> 1819.88
...

Sheet task 1
A1: order id | B1: Order Date | C1: Region | D1: Product Category | E1: Sales Amount | F1: Quantity Sold | G1: Discount % | H1: profit
A2: ab899d2f | B2: 45022 | C2: =PROPER(Table1[[#This Row],[Region]]) -> North | D2: =PROPER(Table1[[#This Row],[Product Category]]) -> Groceries | E2: =ROUND(Table1[[#This Row],[Sales Amount]],1) -> 859.3 | F2: =Table1[[#This Row],[Quantity Sold]] -> 44 | G2: =Table1[[#This Row],[Discount (%)]] -> 37 | H2: =Table1[[#This Row],[Profit]] -> 1653.87 | K2: Sorting and Filtering
A3: 73484eb1 | B3: 45023 | C3: =PROPER(Table1[[#This Row],[Region]]) -> West | D3: =PROPER(Table1[[#This Row],[Product Category]]) -> Groceries | E3: =ROUND(Table1[[#This Row],[Sales Amount]],1) -> 1546.8 | F3: =Table1[[#This Row],[Quantity Sold]] -> 23 | G3: =Table1[[#This Row],[Discount (%)]] -> 33 | H3: =Table1[[#This Row],[Profit]] -> 1932.71
A4: 19395924 | B4: 45024 | C4: =PROPER(Table1[[#This Row],[Region]]) -> East | D4: =PROPER(Table1[[#This Row],[Product Category]]) -> Groceries | E4: =ROUND(Table1[[#This Row],[Sales Amount]],1) -> 4703.6 | F4: =Table1[[#This Row],[Quantity Sold]] -> 31 | G4: =Table1[[#This Row],[Discount (%)]] -> 15 | H4: =Table1[[#This Row],[Profit]] -> 527.47
A5: b3fded3d | B5: 45025 | C5: =PROPER(Table1[[#This Row],[Region]]) -> East | D5: =PROPER(Table1[[#This Row],[Product Category]]) -> Groceries | E5: =ROUND(Table1[[#This Row],[Sales Amount]],1) -> 3377.2 | F5: =Table1[[#This Row],[Quantity Sold]] -> 47 | G5: =Table1[[#This Row],[Discount (%)]] -> 3 | H5: =Table1[[#This Row],[Profit]] -> 482.65
A6: 6e4bdd51 | B6: 45026 | C6: =PROPER(Table1[[#This Row],[Region]]) -> South | D6: =PROPER(Table1[[#This Row],[Product Category]]) -> Clothing | E6: =ROUND(Table1[[#This Row],[Sales Amount]],1) -> 3517.5 | F6: =Table1[[#This Row],[Quantity Sold]] -> 6 | G6: =Table1[[#This Row],[Discount (%)]] -> 28 | H6: =Table1[[#This Row],[Profit]] -> 748.72
A7: 21d88d69 | B7: 45027 | C7: =PROPER(Table1[[#This Row],[Region]]) -> East | D7: =PROPER(Table1[[#This Row],[Product Category]]) -> Furniture | E7: =ROUND(Table1[[#This Row],[Sales Amount]],1) -> 362.6 | F7: =Table1[[#This Row],[Quantity Sold]] -> 19 | G7: =Table1[[#This Row],[Discount (%)]] -> 50 | H7: =Table1[[#This Row],[Profit]] -> 314.71
A8: 9da2704d | B8: 45028 | C8: =PROPER(Table1[[#This Row],[Region]]) -> East | D8: =PROPER(Table1[[#This Row],[Product Category]]) -> Sports | E8: =ROUND(Table1[[#This Row],[Sales Amount]],1) -> 4811.2 | F8: =Table1[[#This Row],[Quantity Sold]] -> 22 | G8: =Table1[[#This Row],[Discount (%)]] -> 18 | H8: =Table1[[#This Row],[Profit]] -> 1372.89
A9: a1bd6815 | B9: 45029 | C9: =PROPER(Table1[[#This Row],[Region]]) -> West | D9: =PROPER(Table1[[#This Row],[Product Category]]) -> Electronics | E9: =ROUND(Table1[[#This Row],[Sales Amount]],1) -> 3565.2 | F9: =Table1[[#This Row],[Quantity Sold]] -> 22 | G9: =Table1[[#This Row],[Discount (%)]] -> 16 | H9: =Table1[[#This Row],[Profit]] -> 1437.3
A10: 0bbd51fc | B10: 45030 | C10: =PROPER(Table1[[#This Row],[Region]]) -> East | D10: =PROPER(Table1[[#This Row],[Product Category]]) -> Clothing | E10: =ROUND(Table1[[#This Row],[Sales Amount]],1) -> 3805.3 | F10: =Table1[[#This Row],[Quantity Sold]] -> 19 | G10: =Table1[[#This Row],[Discount (%)]] -> 3 | H10: =Table1[[#This Row],[Profit]] -> 1537.28
A11: 8bf7e4b3 | B11: 45031 | C11: =PROPER(Table1[[#This Row],[Region]]) -> South | D11: =PROPER(Table1[[#This Row],[Product Category]]) -> Clothing | E11: =ROUND(Table1[[#This Row],[Sales Amount]],1) -> 2178.7 | F11: =Table1[[#This Row],[Quantity Sold]] -> 15 | G11: =Table1[[#This Row],[Discount (%)]] -> 24 | H11: =Table1[[#This Row],[Profit]] -> 1696.65
A12: e6cf1255 | B12: 45032 | C12: =PROPER(Table1[[#This Row],[Region]]) -> West | D12: =PROPER(Table1[[#This Row],[Product Category]]) -> Groceries | E12: =ROUND(Table1[[#This Row],[Sales Amount]],1) -> 2844.9 | F12: =Table1[[#This Row],[Quantity Sold]] -> 34 | G12: =Table1[[#This Row],[Discount (%)]] -> 12 | H12: =Table1[[#This Row],[Profit]] -> 1166.39
A13: 3ba1fc5c | B13: 45033 | C13: =PROPER(Table1[[#This Row],[Region]]) -> West | D13: =PROPER(Table1[[#This Row],[Product Category]]) -> Electronics | E13: =ROUND(Table1[[#This Row],[Sales Amount]],1) -> 3600 | F13: =Table1[[#This Row],[Quantity Sold]] -> 10 | G13: =Table1[[#This Row],[Discount (%)]] -> 2 | H13: =Table1[[#This Row],[Profit]] -> 1632.75
A14: 388ff70d | B14: 45034 | C14: =PROPER(Table1[[#This Row],[Region]]) -> East | D14: =PROPER(Table1[[#This Row],[Product Category]]) -> Sports | E14: =ROUND(Table1[[#This Row],[Sales Amount]],1) -> 941.9 | F14: =Table1[[#This Row],[Quantity Sold]] -> 13 | G14: =Table1[[#This Row],[Discount (%)]] -> 28 | H14: =Table1[[#This Row],[Profit]] -> 646.49
A15: ce2e9002 | B15: 45035 | C15: =PROPER(Table1[[#This Row],[Region]]) -> South | D15: =PROPER(Table1[[#This Row],[Product Category]]) -> Sports | E15: =ROUND(Table1[[#This Row],[Sales Amount]],1) -> 3300.9 | F15: =Table1[[#This Row],[Quantity Sold]] -> 1 | G15: =Table1[[#This Row],[Discount (%)]] -> 48 | H15: =Table1[[#This Row],[Profit]] -> 86.9
A16: a4f9a338 | B16: 45036 | C16: =PROPER(Table1[[#This Row],[Region]]) -> East | D16: =PROPER(Table1[[#This Row],[Product Category]]) -> Groceries | E16: =ROUND(Table1[[#This Row],[Sales Amount]],1) -> 1081.6 | F16: =Table1[[#This Row],[Quantity Sold]] -> 4 | G16: =Table1[[#This Row],[Discount (%)]] -> 19 | H16: =Table1[[#This Row],[Profit]] -> 611.06
... A19: 35358e9c | B19: 45039 | C19: =PROPER(Table1[[#This Row],[Region]]) -> North | D19: =PROPER(Table1[[#This Row],[Product Category]]) -> Clothing | E19: =ROUND(Table1[[#This Row],[Sales Amount]],1) -> 2784.8 | F19: =Table1[[#This Row],[Quantity Sold]] -> 35 | G19: =Table1[[#This Row],[Discount (%)]] -> 40 | H19: =Table1[[#This Row],[Profit]] -> 999.6
A20: 31676338 | B20: 45040 | C20: =PROPER(Table1[[#This Row],[Region]]) -> South | D20: =PROPER(Table1[[#This Row],[Product Category]]) -> Clothing | E20: =ROUND(Table1[[#This Row],[Sales Amount]],1) -> 1083 | F20: =Table1[[#This Row],[Quantity Sold]] -> 8 | G20: =Table1[[#This Row],[Discount (%)]] -> 11 | H20: =Table1[[#This Row],[Profit]] -> 1604.19
A21: 05d72e20 | B21: 45041 | C21: =PROPER(Table1[[#This Row],[Region]]) -> East | D21: =PROPER(Table1[[#This Row],[Product Category]]) -> Clothing | E21: =ROUND(Table1[[#This Row],[Sales Amount]],1) -> 787.8 | F21: =Table1[[#This Row],[Quantity Sold]] -> 47 | G21: =Table1[[#This Row],[Discount (%)]] -> 18 | H21: =Table1[[#This Row],[Profit]] -> 1313.33
A22: 68dbe328 | B22: 45042 | C22: =PROPER(Table1[[#This Row],[Region]]) -> South | D22: =PROPER(Table1[[#This Row],[Product Category]]) -> Furniture | E22: =ROUND(Table1[[#This Row],[Sales Amount]],1) -> 312.7 | F22: =Table1[[#This Row],[Quantity Sold]] -> 36 | G22: =Table1[[#This Row],[Discount (%)]] -> 43 | H22: =Table1[[#This Row],[Profit]] -> 559.52
A23: 78d3f47b | B23: 45043 | C23: =PROPER(Table1[[#This Row],[Region]]) -> East | D23: =PROPER(Table1[[#This Row],[Product Category]]) -> Sports | E23: =ROUND(Table1[[#This Row],[Sales Amount]],1) -> 265.3 | F23: =Table1[[#This Row],[Quantity Sold]] -> 21 | G23: =Table1[[#This Row],[Discount (%)]] -> 36 | H23: =Table1[[#This Row],[Profit]] -> 595.91
A24: 9e4d1fe0 | B24: 45044 | C24: =PROPER(Table1[[#This Row],[Region]]) -> West | D24: =PROPER(Table1[[#This Row],[Product Category]]) -> Furniture | E24: =ROUND(Table1[[#This Row],[Sales Amount]],1) -> 1253.6 | F24: =Table1[[#This Row],[Quantity Sold]] -> 35 | G24: =Table1[[#This Row],[Discount (%)]] -> 14 | H24: =Table1[[#This Row],[Profit]] -> 1653.66
A25: 9215a70e | B25: 45045 | C25: =PROPER(Table1[[#This Row],[Region]]) -> West | D25: =PROPER(Table1[[#This Row],[Product Category]]) -> Clothing | E25: =ROUND(Table1[[#This Row],[Sales Amount]],1) -> 1874.1 | F25: =Table1[[#This Row],[Quantity Sold]] -> 28 | G25: =Table1[[#This Row],[Discount (%)]] -> 23 | H25: =Table1[[#This Row],[Profit]] -> 1783.26
A26: 54ca3433 | B26: 45046 | C26: =PROPER(Table1[[#This Row],[Region]]) -> East | D26: =PROPER(Table1[[#This Row],[Product Category]]) -> Clothing | E26: =ROUND(Table1[[#This Row],[Sales Amount]],1) -> 2561.7 | F26: =Table1[[#This Row],[Quantity Sold]] -> 44 | G26: =Table1[[#This Row],[Discount (%)]] -> 10 | H26: =Table1[[#This Row],[Profit]] -> 800.82
A27: 0ba75cc7 | B27: 45047 | C27: =PROPER(Table1[[#This Row],[Region]]) -> West | D27: =PROPER(Table1[[#This Row],[Product Category]]) -> Sports | E27: =ROUND(Table1[[#This Row],[Sales Amount]],1) -> 1960.7 | F27: =Table1[[#This Row],[Quantity Sold]] -> 50 | G27: =Table1[[#This Row],[Discount (%)]] -> 6 | H27: =Table1[[#This Row],[Profit]] -> 1530.61
A28: 601860b1 | B28: 45048 | C28: =PROPER(Table1[[#This Row],[Region]]) -> East | D28: =PROPER(Table1[[#This Row],[Product Category]]) -> Electronics | E28: =ROUND(Table1[[#This Row],[Sales Amount]],1) -> 2415.4 | F28: =Table1[[#This Row],[Quantity Sold]] -> 35 | G28: =Table1[[#This Row],[Discount (%)]] -> 14 | H28: =Table1[[#This Row],[Profit]] -> 335.57
A29: e393e106 | B29: 45049 | C29: =PROPER(Table1[[#This Row],[Region]]) -> East | D29: =PROPER(Table1[[#This Row],[Product Category]]) -> Electronics | E29: =ROUND(Table1[[#This Row],[Sales Amount]],1) -> 2284.2 | F29: =Table1[[#This Row],[Quantity Sold]] -> 8 | G29: =Table1[[#This Row],[Discount (%)]] -> 41 | H29: =Table1[[#This Row],[Profit]] -> 1866.59
A30: 7ab3d472 | B30: 45050 | C30: =PROPER(Table1[[#This Row],[Region]]) -> West | D30: =PROPER(Table1[[#This Row],[Product Category]]) -> Sports | E30: =ROUND(Table1[[#This Row],[Sales Amount]],1) -> 2118.6 | F30: =Table1[[#This Row],[Quantity Sold]] -> 29 | G30: =Table1[[#This Row],[Discount (%)]] -> 24 | H30: =Table1[[#This Row],[Profit]] -> 702.15
A31: 01d9b1ae | B31: 45051 | C31: =PROPER(Table1[[#This Row],[Region]]) -> South | D31: =PROPER(Table1[[#This Row],[Product Category]]) -> Groceries | E31: =ROUND(Table1[[#This Row],[Sales Amount]],1) -> 4803.6 | F31: =Table1[[#This Row],[Quantity Sold]] -> 11 | G31: =Table1[[#This Row],[Discount (%)]] -> 12 | H31: =Table1[[#This Row],[Profit]] -> 1086.74
A32: 20385cb6 | B32: 45052 | C32: =PROPER(Table1[[#This Row],[Region]]) -> North | D32: =PROPER(Table1[[#This Row],[Product Category]]) -> Groceries | E32: =ROUND(Table1[[#This Row],[Sales Amount]],1) -> 4297 | F32: =Table1[[#This Row],[Quantity Sold]] -> 17 | G32: =Table1[[#This Row],[Discount (%)]] -> 49 | H32: =Table1[[#This Row],[Profit]] -> 678.7
... A69: 92458ed3 | B69: 45089 | C69: =PROPER(Table1[[#This Row],[Region]]) -> North | D69: =PROPER(Table1[[#This Row],[Product Category]]) -> Furniture | E69: =ROUND(Table1[[#This Row],[Sales Amount]],1) -> 1356.6 | F69: =Table1[[#This Row],[Quantity Sold]] -> 2 | G69: =Table1[[#This Row],[Discount (%)]] -> 21 | H69: =Table1[[#This Row],[Profit]] -> 1213.34
A70: 76740552 | B70: 45090 | C70: =PROPER(Table1[[#This Row],[Region]]) -> South | D70: =PROPER(Table1[[#This Row],[Product Category]]) -> Electronics | E70: =ROUND(Table1[[#This Row],[Sales Amount]],1) -> 2905.8 | F70: =Table1[[#This Row],[Quantity Sold]] -> 20 | G70: =Table1[[#This Row],[Discount (%)]] -> 10 | H70: =Table1[[#This Row],[Profit]] -> 1417.43
A71: f92de80d | B71: 45091 | C71: =PROPER(Table1[[#This Row],[Region]]) -> South | D71: =PROPER(Table1[[#This Row],[Product Category]]) -> Furniture | E71: =ROUND(Table1[[#This Row],[Sales Amount]],1) -> 2065.4 | F71: =Table1[[#This Row],[Quantity Sold]] -> 22 | G71: =Table1[[#This Row],[Discount (%)]] -> 15 | H71: =Table1[[#This Row],[Profit]] -> 787.51
A72: 647ff51a | B72: 45092 | C72: =PROPER(Table1[[#This Row],[Region]]) -> East | D72: =PROPER(Table1[[#This Row],[Product Category]]) -> Clothing | E72: =ROUND(Table1[[#This Row],[Sales Amount]],1) -> 272.9 | F72: =Table1[[#This Row],[Quantity Sold]] -> 47 | G72: =Table1[[#This Row],[Discount (%)]] -> 29 | H72: =Table1[[#This Row],[Profit]] -> 1208.68
A73: f8548ec7 | B73: 45093 | C73: =PROPER(Table1[[#This Row],[Region]]) -> East | D73: =PROPER(Table1[[#This Row],[Product Category]]) -> Clothing | E73: =ROUND(Table1[[#This Row],[Sales Amount]],1) -> 4126.4 | F73: =Table1[[#This Row],[Quantity Sold]] -> 34 | G73: =Table1[[#This Row],[Discount (%)]] -> 13 | H73: =Table1[[#This Row],[Profit]] -> 1690.11
A74: 7855a0d2 | B74: 45094 | C74: =PROPER(Table1[[#This Row],[Region]]) -> North | D74: =PROPER(Table1[[#This Row],[Product Category]]) -> Furniture | E74: =ROUND(Table1[[#This Row],[Sales Amount]],1) -> 4204.6 | F74: =Table1[[#This Row],[Quantity Sold]] -> 49 | G74: =Table1[[#This Row],[Discount (%)]] -> 1 | H74: =Table1[[#This Row],[Profit]] -> 1534.82
A75: bf586512 | B75: 45095 | C75: =PROPER(Table1[[#This Row],[Region]]) -> West | D75: =PROPER(Table1[[#This Row],[Product Category]]) -> Clothing | E75: =ROUND(Table1[[#This Row],[Sales Amount]],1) -> 2131 | F75: =Table1[[#This Row],[Quantity Sold]] -> 7 | G75: =Table1[[#This Row],[Discount (%)]] -> 29 | H75: =Table1[[#This Row],[Profit]] -> 679.16
A76: deea1965 | B76: 45096 | C76: =PROPER(Table1[[#This Row],[Region]]) -> South | D76: =PROPER(Table1[[#This Row],[Product Category]]) -> Furniture | E76: =ROUND(Table1[[#This Row],[Sales Amount]],1) -> 1253.3 | F76: =Table1[[#This Row],[Quantity Sold]] -> 4 | G76: =Table1[[#This Row],[Discount (%)]] -> 48 | H76: =Table1[[#This Row],[Profit]] -> 317.33
A77: a0a8290f | B77: 45097 | C77: =PROPER(Table1[[#This Row],[Region]]) -> South | D77: =PROPER(Table1[[#This Row],[Product Category]]) -> Sports | E77: =ROUND(Table1[[#This Row],[Sales Amount]],1) -> 1050.3 | F77: =Table1[[#This Row],[Quantity Sold]] -> 30 | G77: =Table1[[#This Row],[Discount (%)]] -> 4 | H77: =Table1[[#This Row],[Profit]] -> 423.5
A78: 077a9429 | B78: 45098 | C78: =PROPER(Table1[[#This Row],[Region]]) -> North | D78: =PROPER(Table1[[#This Row],[Product Category]]) -> Furniture | E78: =ROUND(Table1[[#This Row],[Sales Amount]],1) -> 1269.1 | F78: =Table1[[#This Row],[Quantity Sold]] -> 3 | G78: =Table1[[#This Row],[Discount (%)]] -> 7 | H78: =Table1[[#This Row],[Profit]] -> 1819.88
...

Sheet task 2
A1: TRIM | G1: UPPER | L1: LOWER
B3: Trim region | C3: Trim product | G3: Upper region | H3: Upper product | L3: lower region | M3: lower product
B4: =TRIM(Table24[[#This Row],[Region]]) -> East | C4: =TRIM(Table24[[#This Row],[Product Category]]) -> Groceries | G4: =UPPER('task 1'!C2) -> NORTH | H4: =UPPER(C4) -> GROCERIES | L4: =LOWER(G4) -> north | M4: =LOWER(H4) -> groceries
B5: =TRIM(Table24[[#This Row],[Region]]) -> East | C5: =TRIM(Table24[[#This Row],[Product Category]]) -> Groceries | G5: =UPPER('task 1'!C3) -> WEST | H5: =UPPER(C5) -> GROCERIES | L5: =LOWER(G5) -> west | M5: =LOWER(H5) -> groceries
B6: =TRIM(Table24[[#This Row],[Region]]) -> South | C6: =TRIM(Table24[[#This Row],[Product Category]]) -> Clothing | G6: =UPPER('task 1'!C4) -> EAST | H6: =UPPER(C6) -> CLOTHING | L6: =LOWER(G6) -> east | M6: =LOWER(H6) -> clothing
B7: =TRIM(Table24[[#This Row],[Region]]) -> East | C7: =TRIM(Table24[[#This Row],[Product Category]]) -> Furniture | G7: =UPPER('task 1'!C5) -> EAST | H7: =UPPER(C7) -> FURNITURE | L7: =LOWER(G7) -> east | M7: =LOWER(H7) -> furniture
B8: =TRIM(Table24[[#This Row],[Region]]) -> East | C8: =TRIM(Table24[[#This Row],[Product Category]]) -> Sports | G8: =UPPER('task 1'!C6) -> SOUTH | H8: =UPPER(C8) -> SPORTS | L8: =LOWER(G8) -> south | M8: =LOWER(H8) -> sports
B9: =TRIM(Table24[[#This Row],[Region]]) -> West | C9: =TRIM(Table24[[#This Row],[Product Category]]) -> Electronics | G9: =UPPER('task 1'!C7) -> EAST | H9: =UPPER(C9) -> ELECTRONICS | L9: =LOWER(G9) -> east | M9: =LOWER(H9) -> electronics
B10: =TRIM(Table24[[#This Row],[Region]]) -> East | C10: =TRIM(Table24[[#This Row],[Product Category]]) -> Clothing | G10: =UPPER('task 1'!C8) -> EAST | H10: =UPPER(C10) -> CLOTHING | L10: =LOWER(G10) -> east | M10: =LOWER(H10) -> clothing
B11: =TRIM(Table24[[#This Row],[Region]]) -> South | C11: =TRIM(Table24[[#This Row],[Product Category]]) -> Clothing | G11: =UPPER('task 1'!C9) -> WEST | H11: =UPPER(C11) -> CLOTHING | L11: =LOWER(G11) -> west | M11: =LOWER(H11) -> clothing
B12: =TRIM(Table24[[#This Row],[Region]]) -> West | C12: =TRIM(Table24[[#This Row],[Product Category]]) -> Groceries | G12: =UPPER('task 1'!C10) -> EAST | H12: =UPPER(C12) -> GROCERIES | L12: =LOWER(G12) -> east | M12: =LOWER(H12) -> groceries
B13: =TRIM(Table24[[#This Row],[Region]]) -> West | C13: =TRIM(Table24[[#This Row],[Product Category]]) -> Electronics | G13: =UPPER('task 1'!C11) -> SOUTH | H13: =UPPER(C13) -> ELECTRONICS | L13: =LOWER(G13) -> south | M13: =LOWER(H13) -> electronics
B14: =TRIM(Table24[[#This Row],[Region]]) -> East | C14: =TRIM(Table24[[#This Row],[Product Category]]) -> Sports | G14: =UPPER('task 1'!C12) -> WEST | H14: =UPPER(C14) -> SPORTS | L14: =LOWER(G14) -> west | M14: =LOWER(H14) -> sports
B15: =TRIM(Table24[[#This Row],[Region]]) -> South | C15: =TRIM(Table24[[#This Row],[Product Category]]) -> Sports | G15: =UPPER('task 1'!C13) -> WEST | H15: =UPPER(C15) -> SPORTS | L15: =LOWER(G15) -> west | M15: =LOWER(H15) -> sports
... B3998: =TRIM(Table24[[#This Row],[Region]]) -> South | C3998: =TRIM(Table24[[#This Row],[Product Category]]) -> Electronics | G3998: =UPPER('task 1'!C3996) -> EAST | H3998: =UPPER(C3998) -> ELECTRONICS | L3998: =LOWER(G3998) -> east | M3998: =LOWER(H3998) -> electronics

Sheet task 3
A1: order id | B1: Order Date | C1: Region | D1: Product Category | E1: Sales Amount | F1: Quantity Sold | G1: Discount % | H1: profit
A2: ab899d2f | B2: 45022 | C2: =PROPER(Table1[[#This Row],[Region]]) -> North | D2: =PROPER(Table1[[#This Row],[Product Category]]) -> Groceries | E2: =ROUND(Table1[[#This Row],[Sales Amount]],1) -> 859.3 | F2: =Table1[[#This Row],[Quantity Sold]] -> 44 | G2: =Table1[[#This Row],[Discount (%)]] -> 37 | H2: =Table1[[#This Row],[Profit]] -> 1653.87
A3: 73484eb1 | B3: 45023 | C3: =PROPER(Table1[[#This Row],[Region]]) -> West | D3: =PROPER(Table1[[#This Row],[Product Category]]) -> Groceries | E3: =ROUND(Table1[[#This Row],[Sales Amount]],1) -> 1546.8 | F3: =Table1[[#This Row],[Quantity Sold]] -> 23 | G3: =Table1[[#This Row],[Discount (%)]] -> 33 | H3: =Table1[[#This Row],[Profit]] -> 1932.71 | M3: Average by region
A4: 19395924 | B4: 45024 | C4: =PROPER(Table1[[#This Row],[Region]]) -> East | D4: =PROPER(Table1[[#This Row],[Product Category]]) -> Groceries | E4: =ROUND(Table1[[#This Row],[Sales Amount]],1) -> 4703.6 | F4: =Table1[[#This Row],[Quantity Sold]] -> 31 | G4: =Table1[[#This Row],[Discount (%)]] -> 15 | H4: =Table1[[#This Row],[Profit]] -> 527.47
A5: b3fded3d | B5: 45025 | C5: =PROPER(Table1[[#This Row],[Region]]) -> East | D5: =PROPER(Table1[[#This Row],[Product Category]]) -> Groceries | E5: =ROUND(Table1[[#This Row],[Sales Amount]],1) -> 3377.2 | F5: =Table1[[#This Row],[Quantity Sold]] -> 47 | G5: =Table1[[#This Row],[Discount (%)]] -> 3 | H5: =Table1[[#This Row],[Profit]] -> 482.65 | M5: North | N5: =AVERAGEIF(Table246[Region],"North",Table246[Sales Amount]) -> 2572.97
A6: 6e4bdd51 | B6: 45026 | C6: =PROPER(Table1[[#This Row],[Region]]) -> South | D6: =PROPER(Table1[[#This Row],[Product Category]]) -> Clothing | E6: =ROUND(Table1[[#This Row],[Sales Amount]],1) -> 3517.5 | F6: =Table1[[#This Row],[Quantity Sold]] -> 6 | G6: =Table1[[#This Row],[Discount (%)]] -> 28 | H6: =Table1[[#This Row],[Profit]] -> 748.72 | M6: west | N6: =AVERAGEIF(Table246[Region],"West",Table246[Sales Amount]) -> 2537.6247
A7: 21d88d69 | B7: 45027 | C7: =PROPER(Table1[[#This Row],[Region]]) -> East | D7: =PROPER(Table1[[#This Row],[Product Category]]) -> Furniture | E7: =ROUND(Table1[[#This Row],[Sales Amount]],1) -> 362.6 | F7: =Table1[[#This Row],[Quantity Sold]] -> 19 | G7: =Table1[[#This Row],[Discount (%)]] -> 50 | H7: =Table1[[#This Row],[Profit]] -> 314.71 | M7: south | N7: =AVERAGEIF(Table246[Region],"South",Table246[Sales Amount]) -> 2494.4148
A8: 9da2704d | B8: 45028 | C8: =PROPER(Table1[[#This Row],[Region]]) -> East | D8: =PROPER(Table1[[#This Row],[Product Category]]) -> Sports | E8: =ROUND(Table1[[#This Row],[Sales Amount]],1) -> 4811.2 | F8: =Table1[[#This Row],[Quantity Sold]] -> 22 | G8: =Table1[[#This Row],[Discount (%)]] -> 18 | H8: =Table1[[#This Row],[Profit]] -> 1372.89 | M8: east | N8: =AVERAGEIF(Table246[Region],"East",Table246[Sales Amount]) -> 2507.2789
A9: a1bd6815 | B9: 45029 | C9: =PROPER(Table1[[#This Row],[Region]]) -> West | D9: =PROPER(Table1[[#This Row],[Product Category]]) -> Electronics | E9: =ROUND(Table1[[#This Row],[Sales Amount]],1) -> 3565.2 | F9: =Table1[[#This Row],[Quantity Sold]] -> 22 | G9: =Table1[[#This Row],[Discount (%)]] -> 16 | H9: =Table1[[#This Row],[Profit]] -> 1437.3
A10: 0bbd51fc | B10: 45030 | C10: =PROPER(Table1[[#This Row],[Region]]) -> East | D10: =PROPER(Table1[[#This Row],[Product Category]]) -> Clothing | E10: =ROUND(Table1[[#This Row],[Sales Amount]],1) -> 3805.3 | F10: =Table1[[#This Row],[Quantity Sold]] -> 19 | G10: =Table1[[#This Row],[Discount (%)]] -> 3 | H10: =Table1[[#This Row],[Profit]] -> 1537.28
A11: 8bf7e4b3 | B11: 45031 | C11: =PROPER(Table1[[#This Row],[Region]]) -> South | D11: =PROPER(Table1[[#This Row],[Product Category]]) -> Clothing | E11: =ROUND(Table1[[#This Row],[Sales Amount]],1) -> 2178.7 | F11: =Table1[[#This Row],[Quantity Sold]] -> 15 | G11: =Table1[[#This Row],[Discount (%)]] -> 24 | H11: =Table1[[#This Row],[Profit]] -> 1696.65
A12: e6cf1255 | B12: 45032 | C12: =PROPER(Table1[[#This Row],[Region]]) -> West | D12: =PROPER(Table1[[#This Row],[Product Category]]) -> Groceries | E12: =ROUND(Table1[[#This Row],[Sales Amount]],1) -> 2844.9 | F12: =Table1[[#This Row],[Quantity Sold]] -> 34 | G12: =Table1[[#This Row],[Discount (%)]] -> 12 | H12: =Table1[[#This Row],[Profit]] -> 1166.39
A13: 3ba1fc5c | B13: 45033 | C13: =PROPER(Table1[[#This Row],[Region]]) -> West | D13: =PROPER(Table1[[#This Row],[Product Category]]) -> Electronics | E13: =ROUND(Table1[[#This Row],[Sales Amount]],1) -> 3600 | F13: =Table1[[#This Row],[Quantity Sold]] -> 10 | G13: =Table1[[#This Row],[Discount (%)]] -> 2 | H13: =Table1[[#This Row],[Profit]] -> 1632.75
A14: 388ff70d | B14: 45034 | C14: =PROPER(Table1[[#This Row],[Region]]) -> East | D14: =PROPER(Table1[[#This Row],[Product Category]]) -> Sports | E14: =ROUND(Table1[[#This Row],[Sales Amount]],1) -> 941.9 | F14: =Table1[[#This Row],[Quantity Sold]] -> 13 | G14: =Table1[[#This Row],[Discount (%)]] -> 28 | H14: =Table1[[#This Row],[Profit]] -> 646.49
A15: ce2e9002 | B15: 45035 | C15: =PROPER(Table1[[#This Row],[Region]]) -> South | D15: =PROPER(Table1[[#This Row],[Product Category]]) -> Sports | E15: =ROUND(Table1[[#This Row],[Sales Amount]],1) -> 3300.9 | F15: =Table1[[#This Row],[Quantity Sold]] -> 1 | G15: =Table1[[#This Row],[Discount (%)]] -> 48 | H15: =Table1[[#This Row],[Profit]] -> 86.9
A16: a4f9a338 | B16: 45036 | C16: =PROPER(Table1[[#This Row],[Region]]) -> East | D16: =PROPER(Table1[[#This Row],[Product Category]]) -> Groceries | E16: =ROUND(Table1[[#This Row],[Sales Amount]],1) -> 1081.6 | F16: =Table1[[#This Row],[Quantity Sold]] -> 4 | G16: =Table1[[#This Row],[Discount (%)]] -> 19 | H16: =Table1[[#This Row],[Profit]] -> 611.06
A17: eadceaa8 | B17: 45037 | C17: =PROPER(Table1[[#This Row],[Region]]) -> East | D17: =PROPER(Table1[[#This Row],[Product Category]]) -> Furniture | E17: =ROUND(Table1[[#This Row],[Sales Amount]],1) -> 3455.7 | F17: =Table1[[#This Row],[Quantity Sold]] -> 39 | G17: =Table1[[#This Row],[Discount (%)]] -> 21 | H17: =Table1[[#This Row],[Profit]] -> 208.1
A18: ad7f9de9 | B18: 45038 | C18: =PROPER(Table1[[#This Row],[Region]]) -> South | D18: =PROPER(Table1[[#This Row],[Product Category]]) -> Groceries | E18: =ROUND(Table1[[#This Row],[Sales Amount]],1) -> 2381.5 | F18: =Table1[[#This Row],[Quantity Sold]] -> 16 | G18: =Table1[[#This Row],[Discount (%)]] -> 39 | H18: =Table1[[#This Row],[Profit]] -> 1083.96
A19: 35358e9c | B19: 45039 | C19: =PROPER(Table1[[#This Row],[Region]]) -> North | D19: =PROPER(Table1[[#This Row],[Product Category]]) -> Clothing | E19: =ROUND(Table1[[#This Row],[Sales Amount]],1) -> 2784.8 | F19: =Table1[[#This Row],[Quantity Sold]] -> 35 | G19: =Table1[[#This Row],[Discount (%)]] -> 40 | H19: =Table1[[#This Row],[Profit]] -> 999.6
A20: 31676338 | B20: 45040 | C20: =PROPER(Table1[[#This Row],[Region]]) -> South | D20: =PROPER(Table1[[#This Row],[Product Category]]) -> Clothing | E20: =ROUND(Table1[[#This Row],[Sales Amount]],1) -> 1083 | F20: =Table1[[#This Row],[Quantity Sold]] -> 8 | G20: =Table1[[#This Row],[Discount (%)]] -> 11 | H20: =Table1[[#This Row],[Profit]] -> 1604.19
A21: 05d72e20 | B21: 45041 | C21: =PROPER(Table1[[#This Row],[Region]]) -> East | D21: =PROPER(Table1[[#This Row],[Product Category]]) -> Clothing | E21: =ROUND(Table1[[#This Row],[Sales Amount]],1) -> 787.8 | F21: =Table1[[#This Row],[Quantity Sold]] -> 47 | G21: =Table1[[#This Row],[Discount (%)]] -> 18 | H21: =Table1[[#This Row],[Profit]] -> 1313.33
A22: 68dbe328 | B22: 45042 | C22: =PROPER(Table1[[#This Row],[Region]]) -> South | D22: =PROPER(Table1[[#This Row],[Product Category]]) -> Furniture | E22: =ROUND(Table1[[#This Row],[Sales Amount]],1) -> 312.7 | F22: =Table1[[#This Row],[Quantity Sold]] -> 36 | G22: =Table1[[#This Row],[Discount (%)]] -> 43 | H22: =Table1[[#This Row],[Profit]] -> 559.52
A23: 78d3f47b | B23: 45043 | C23: =PROPER(Table1[[#This Row],[Region]]) -> East | D23: =PROPER(Table1[[#This Row],[Product Category]]) -> Sports | E23: =ROUND(Table1[[#This Row],[Sales Amount]],1) -> 265.3 | F23: =Table1[[#This Row],[Quantity Sold]] -> 21 | G23: =Table1[[#This Row],[Discount (%)]] -> 36 | H23: =Table1[[#This Row],[Profit]] -> 595.91
A24: 9e4d1fe0 | B24: 45044 | C24: =PROPER(Table1[[#This Row],[Region]]) -> West | D24: =PROPER(Table1[[#This Row],[Product Category]]) -> Furniture | E24: =ROUND(Table1[[#This Row],[Sales Amount]],1) -> 1253.6 | F24: =Table1[[#This Row],[Quantity Sold]] -> 35 | G24: =Table1[[#This Row],[Discount (%)]] -> 14 | H24: =Table1[[#This Row],[Profit]] -> 1653.66
A25: 9215a70e | B25: 45045 | C25: =PROPER(Table1[[#This Row],[Region]]) -> West | D25: =PROPER(Table1[[#This Row],[Product Category]]) -> Clothing | E25: =ROUND(Table1[[#This Row],[Sales Amount]],1) -> 1874.1 | F25: =Table1[[#This Row],[Quantity Sold]] -> 28 | G25: =Table1[[#This Row],[Discount (%)]] -> 23 | H25: =Table1[[#This Row],[Profit]] -> 1783.26
A26: 54ca3433 | B26: 45046 | C26: =PROPER(Table1[[#This Row],[Region]]) -> East | D26: =PROPER(Table1[[#This Row],[Product Category]]) -> Clothing | E26: =ROUND(Table1[[#This Row],[Sales Amount]],1) -> 2561.7 | F26: =Table1[[#This Row],[Quantity Sold]] -> 44 | G26: =Table1[[#This Row],[Discount (%)]] -> 10 | H26: =Table1[[#This Row],[Profit]] -> 800.82
A27: 0ba75cc7 | B27: 45047 | C27: =PROPER(Table1[[#This Row],[Region]]) -> West | D27: =PROPER(Table1[[#This Row],[Product Category]]) -> Sports | E27: =ROUND(Table1[[#This Row],[Sales Amount]],1) -> 1960.7 | F27: =Table1[[#This Row],[Quantity Sold]] -> 50 | G27: =Table1[[#This Row],[Discount (%)]] -> 6 | H27: =Table1[[#This Row],[Profit]] -> 1530.61
A28: 601860b1 | B28: 45048 | C28: =PROPER(Table1[[#This Row],[Region]]) -> East | D28: =PROPER(Table1[[#This Row],[Product Category]]) -> Electronics | E28: =ROUND(Table1[[#This Row],[Sales Amount]],1) -> 2415.4 | F28: =Table1[[#This Row],[Quantity Sold]] -> 35 | G28: =Table1[[#This Row],[Discount (%)]] -> 14 | H28: =Table1[[#This Row],[Profit]] -> 335.57
A29: e393e106 | B29: 45049 | C29: =PROPER(Table1[[#This Row],[Region]]) -> East | D29: =PROPER(Table1[[#This Row],[Product Category]]) -> Electronics | E29: =ROUND(Table1[[#This Row],[Sales Amount]],1) -> 2284.2 | F29: =Table1[[#This Row],[Quantity Sold]] -> 8 | G29: =Table1[[#This Row],[Discount (%)]] -> 41 | H29: =Table1[[#This Row],[Profit]] -> 1866.59
A30: 7ab3d472 | B30: 45050 | C30: =PROPER(Table1[[#This Row],[Region]]) -> West | D30: =PROPER(Table1[[#This Row],[Product Category]]) -> Sports | E30: =ROUND(Table1[[#This Row],[Sales Amount]],1) -> 2118.6 | F30: =Table1[[#This Row],[Quantity Sold]] -> 29 | G30: =Table1[[#This Row],[Discount (%)]] -> 24 | H30: =Table1[[#This Row],[Profit]] -> 702.15
A31: 01d9b1ae | B31: 45051 | C31: =PROPER(Table1[[#This Row],[Region]]) -> South | D31: =PROPER(Table1[[#This Row],[Product Category]]) -> Groceries | E31: =ROUND(Table1[[#This Row],[Sales Amount]],1) -> 4803.6 | F31: =Table1[[#This Row],[Quantity Sold]] -> 11 | G31: =Table1[[#This Row],[Discount (%)]] -> 12 | H31: =Table1[[#This Row],[Profit]] -> 1086.74
A32: 20385cb6 | B32: 45052 | C32: =PROPER(Table1[[#This Row],[Region]]) -> North | D32: =PROPER(Table1[[#This Row],[Product Category]]) -> Groceries | E32: =ROUND(Table1[[#This Row],[Sales Amount]],1) -> 4297 | F32: =Table1[[#This Row],[Quantity Sold]] -> 17 | G32: =Table1[[#This Row],[Discount (%)]] -> 49 | H32: =Table1[[#This Row],[Profit]] -> 678.7
... A69: 92458ed3 | B69: 45089 | C69: =PROPER(Table1[[#This Row],[Region]]) -> North | D69: =PROPER(Table1[[#This Row],[Product Category]]) -> Furniture | E69: =ROUND(Table1[[#This Row],[Sales Amount]],1) -> 1356.6 | F69: =Table1[[#This Row],[Quantity Sold]] -> 2 | G69: =Table1[[#This Row],[Discount (%)]] -> 21 | H69: =Table1[[#This Row],[Profit]] -> 1213.34
A70: 76740552 | B70: 45090 | C70: =PROPER(Table1[[#This Row],[Region]]) -> South | D70: =PROPER(Table1[[#This Row],[Product Category]]) -> Electronics | E70: =ROUND(Table1[[#This Row],[Sales Amount]],1) -> 2905.8 | F70: =Table1[[#This Row],[Quantity Sold]] -> 20 | G70: =Table1[[#This Row],[Discount (%)]] -> 10 | H70: =Table1[[#This Row],[Profit]] -> 1417.43
A71: f92de80d | B71: 45091 | C71: =PROPER(Table1[[#This Row],[Region]]) -> South | D71: =PROPER(Table1[[#This Row],[Product Category]]) -> Furniture | E71: =ROUND(Table1[[#This Row],[Sales Amount]],1) -> 2065.4 | F71: =Table1[[#This Row],[Quantity Sold]] -> 22 | G71: =Table1[[#This Row],[Discount (%)]] -> 15 | H71: =Table1[[#This Row],[Profit]] -> 787.51
A72: 647ff51a | B72: 45092 | C72: =PROPER(Table1[[#This Row],[Region]]) -> East | D72: =PROPER(Table1[[#This Row],[Product Category]]) -> Clothing | E72: =ROUND(Table1[[#This Row],[Sales Amount]],1) -> 272.9 | F72: =Table1[[#This Row],[Quantity Sold]] -> 47 | G72: =Table1[[#This Row],[Discount (%)]] -> 29 | H72: =Table1[[#This Row],[Profit]] -> 1208.68
A73: f8548ec7 | B73: 45093 | C73: =PROPER(Table1[[#This Row],[Region]]) -> East | D73: =PROPER(Table1[[#This Row],[Product Category]]) -> Clothing | E73: =ROUND(Table1[[#This Row],[Sales Amount]],1) -> 4126.4 | F73: =Table1[[#This Row],[Quantity Sold]] -> 34 | G73: =Table1[[#This Row],[Discount (%)]] -> 13 | H73: =Table1[[#This Row],[Profit]] -> 1690.11
A74: 7855a0d2 | B74: 45094 | C74: =PROPER(Table1[[#This Row],[Region]]) -> North | D74: =PROPER(Table1[[#This Row],[Product Category]]) -> Furniture | E74: =ROUND(Table1[[#This Row],[Sales Amount]],1) -> 4204.6 | F74: =Table1[[#This Row],[Quantity Sold]] -> 49 | G74: =Table1[[#This Row],[Discount (%)]] -> 1 | H74: =Table1[[#This Row],[Profit]] -> 1534.82
A75: bf586512 | B75: 45095 | C75: =PROPER(Table1[[#This Row],[Region]]) -> West | D75: =PROPER(Table1[[#This Row],[Product Category]]) -> Clothing | E75: =ROUND(Table1[[#This Row],[Sales Amount]],1) -> 2131 | F75: =Table1[[#This Row],[Quantity Sold]] -> 7 | G75: =Table1[[#This Row],[Discount (%)]] -> 29 | H75: =Table1[[#This Row],[Profit]] -> 679.16
A76: deea1965 | B76: 45096 | C76: =PROPER(Table1[[#This Row],[Region]]) -> South | D76: =PROPER(Table1[[#This Row],[Product Category]]) -> Furniture | E76: =ROUND(Table1[[#This Row],[Sales Amount]],1) -> 1253.3 | F76: =Table1[[#This Row],[Quantity Sold]] -> 4 | G76: =Table1[[#This Row],[Discount (%)]] -> 48 | H76: =Table1[[#This Row],[Profit]] -> 317.33
...

Sheet task 4
A1: Sum Average
C6: region | D6: sum of region | J6: Category | K6: Average
C7: North | D7: =SUMIF(Table246[Region],"North",Table246[Sales Amount]) -> 2536948.4 | J7: Average Discount of Furniture | K7: =AVERAGEIF(Table246[Product Category],"Furniture",Table246[Discount %]) -> 25.215951
C8: West | D8: =SUMIF(Table246[Region],"West",Table246[Sales Amount]) -> 2479259.3 | J8: Average profit of Furniture | K8: =AVERAGEIF(Table246[Product Category],"Furniture",Table246[profit]) -> 1022.3432
C9: East | D9: =SUMIF(Table246[Region],"East",Table246[Sales Amount]) -> 2592526.4
C10: South | D10: =SUMIF(Table246[Region],"South",Table246[Sales Amount]) -> 2494414.8

Sheet task 5
A1: SUM OF SALES BY REGION SUM OF PROFIT BY REGION
C4: Region | D4: Sum of Sales Amount | J4: Region | K4: Sum of profit
C5: East | D5: 2592526.4 | J5: East | K5: 1049790.1
C6: North | D6: 2536948.4 | J6: North | K6: 969077.71
C7: South | D7: 2494414.8 | J7: South | K7: 1010902.6
C8: West | D8: 2479259.3 | J8: West | K8: 998358.03
C9: Grand Total | D9: 10103149 | J9: Grand Total | K9: 4028128.4
A20: BY USING PIVOT TABLE
U61: Region | V61: Sum of Sales Amount
U62: Clothing | V62: 2156010.8
U63: Electronics | V63: 2047839.5
U64: Furniture | V64: 2046524.5
U65: Groceries | V65: 1864229.2
U66: Sports | V66: 1988544.9
U67: Grand Total | V67: 10103149

Sheet task 6
A1: TOTAL SALES BY REGION | L1: TOTAL SALES BY CATEGORY

Sheet task 7
A1: REGRESSION ANALYSIS
E5: Discount % | F5: profit
E6: =Table1[[#This Row],[Discount (%)]] -> 28 | F6: =Table1[[#This Row],[Profit]] -> 748.72
E7: =Table1[[#This Row],[Discount (%)]] -> 50 | F7: =Table1[[#This Row],[Profit]] -> 314.71
E8: =Table1[[#This Row],[Discount (%)]] -> 18 | F8: =Table1[[#This Row],[Profit]] -> 1372.89
E9: =Table1[[#This Row],[Discount (%)]] -> 16 | F9: =Table1[[#This Row],[Profit]] -> 1437.3
E10: =Table1[[#This Row],[Discount (%)]] -> 3 | F10: =Table1[[#This Row],[Profit]] -> 1537.28
E11: =Table1[[#This Row],[Discount (%)]] -> 24 | F11: =Table1[[#This Row],[Profit]] -> 1696.65
E12: =Table1[[#This Row],[Discount (%)]] -> 12 | F12: =Table1[[#This Row],[Profit]] -> 1166.39
E13: =Table1[[#This Row],[Discount (%)]] -> 2 | F13: =Table1[[#This Row],[Profit]] -> 1632.75
E14: =Table1[[#This Row],[Discount (%)]] -> 28 | F14: =Table1[[#This Row],[Profit]] -> 646.49
E15: =Table1[[#This Row],[Discount (%)]] -> 48 | F15: =Table1[[#This Row],[Profit]] -> 86.9
E16: =Table1[[#This Row],[Discount (%)]] -> 19 | F16: =Table1[[#This Row],[Profit]] -> 611.06
E17: =Table1[[#This Row],[Discount (%)]] -> 21 | F17: =Table1[[#This Row],[Profit]] -> 208.1
... E4002: =Table1[[#This Row],[Discount (%)]] -> #VALUE! | F4002: =Table1[[#This Row],[Profit]] -> #VALUE!

Sheet task 8
A1: STACKED BAR CHART
D9: Region | E9: Sum of Sales Amount
D10: East | E10: 2592526.4
D11: North | E11: 2536948.4
D12: South | E12: 2494414.8
D13: West | E13: 2479259.3
D14: Grand Total | E14: 10103149
D28: Region | E28: Total Sales by Region
D29: Clothing | E29: 2156010.8
D30: Electronics | E30: 2047839.5
D31: Furniture | E31: 2046524.5
D32: Groceries | E32: 1864229.2
D33: Sports | E33: 1988544.9
D34: Grand Total | E34: 10103149

Sheet Dashboard

Sheet task 10
A1: order id | B1: Order Date | C1: Region | D1: Product Category | E1: Sales Amount | F1: Quantity Sold | G1: Discount % | H1: profit | I1: profit Margin
A2: ab899d2f | B2: 45022 | C2: =PROPER(Table1[[#This Row],[Region]]) -> North | D2: =PROPER(Table1[[#This Row],[Product Category]]) -> Groceries | E2: =ROUND(Table1[[#This Row],[Sales Amount]],1) -> 859.3 | F2: =Table1[[#This Row],[Quantity Sold]] -> 44 | G2: =Table1[[#This Row],[Discount (%)]] -> 37 | H2: =Table1[[#This Row],[Profit]] -> 1653.87 | I2: =Table24610[[#This Row],[profit]]/Table24610[[#This Row],[Sales Amount]] -> 1.9246712
A3: 73484eb1 | B3: 45023 | C3: =PROPER(Table1[[#This Row],[Region]]) -> West | D3: =PROPER(Table1[[#This Row],[Product Category]]) -> Groceries | E3: =ROUND(Table1[[#This Row],[Sales Amount]],1) -> 1546.8 | F3: =Table1[[#This Row],[Quantity Sold]] -> 23 | G3: =Table1[[#This Row],[Discount (%)]] -> 33 | H3: =Table1[[#This Row],[Profit]] -> 1932.71 | I3: =Table24610[[#This Row],[profit]]/Table24610[[#This Row],[Sales Amount]] -> 1.2494893 | M3: Adding colum and finding profit margin
A4: 19395924 | B4: 45024 | C4: =PROPER(Table1[[#This Row],[Region]]) -> East | D4: =PROPER(Table1[[#This Row],[Product Category]]) -> Groceries | E4: =ROUND(Table1[[#This Row],[Sales Amount]],1) -> 4703.6 | F4: =Table1[[#This Row],[Quantity Sold]] -> 31 | G4: =Table1[[#This Row],[Discount (%)]] -> 15 | H4: =Table1[[#This Row],[Profit]] -> 527.47 | I4: =Table24610[[#This Row],[profit]]/Table24610[[#This Row],[Sales Amount]] -> 0.11214176
A5: b3fded3d | B5: 45025 | C5: =PROPER(Table1[[#This Row],[Region]]) -> East | D5: =PROPER(Table1[[#This Row],[Product Category]]) -> Groceries | E5: =ROUND(Table1[[#This Row],[Sales Amount]],1) -> 3377.2 | F5: =Table1[[#This Row],[Quantity Sold]] -> 47 | G5: =Table1[[#This Row],[Discount (%)]] -> 3 | H5: =Table1[[#This Row],[Profit]] -> 482.65 | I5: =Table24610[[#This Row],[profit]]/Table24610[[#This Row],[Sales Amount]] -> 0.14291425 | M5: Highlight profit margin
